[2022-06-08 12:21:48,396] {taskinstance.py:1159} INFO - Dependencies all met for <TaskInstance: spotify_dag.Whole_Spotify_ETL scheduled__2022-06-08T05:21:00+00:00 [queued]>
[2022-06-08 12:21:48,408] {taskinstance.py:1159} INFO - Dependencies all met for <TaskInstance: spotify_dag.Whole_Spotify_ETL scheduled__2022-06-08T05:21:00+00:00 [queued]>
[2022-06-08 12:21:48,408] {taskinstance.py:1356} INFO - 
--------------------------------------------------------------------------------
[2022-06-08 12:21:48,408] {taskinstance.py:1357} INFO - Starting attempt 1 of 2
[2022-06-08 12:21:48,409] {taskinstance.py:1358} INFO - 
--------------------------------------------------------------------------------
[2022-06-08 12:21:48,428] {taskinstance.py:1377} INFO - Executing <Task(PythonOperator): Whole_Spotify_ETL> on 2022-06-08 05:21:00+00:00
[2022-06-08 12:21:48,431] {standard_task_runner.py:52} INFO - Started process 104734 to run task
[2022-06-08 12:21:48,437] {standard_task_runner.py:79} INFO - Running: ['airflow', 'tasks', 'run', 'spotify_dag', 'Whole_Spotify_ETL', 'scheduled__2022-06-08T05:21:00+00:00', '--job-id', '349', '--raw', '--subdir', 'DAGS_FOLDER/spotify_dag.py', '--cfg-path', '/tmp/tmpjz_764rp', '--error-file', '/tmp/tmpjqx32fbs']
[2022-06-08 12:21:48,438] {standard_task_runner.py:80} INFO - Job 349: Subtask Whole_Spotify_ETL
[2022-06-08 12:21:48,510] {task_command.py:370} INFO - Running <TaskInstance: spotify_dag.Whole_Spotify_ETL scheduled__2022-06-08T05:21:00+00:00 [running]> on host kubernetes-worker
[2022-06-08 12:21:48,606] {taskinstance.py:1569} INFO - Exporting the following env vars:
AIRFLOW_CTX_DAG_EMAIL=wabuyajames@gmail.com
AIRFLOW_CTX_DAG_OWNER=airflow
AIRFLOW_CTX_DAG_ID=spotify_dag
AIRFLOW_CTX_TASK_ID=Whole_Spotify_ETL
AIRFLOW_CTX_EXECUTION_DATE=2022-06-08T05:21:00+00:00
AIRFLOW_CTX_TRY_NUMBER=1
AIRFLOW_CTX_DAG_RUN_ID=scheduled__2022-06-08T05:21:00+00:00
[2022-06-08 12:21:48,607] {taskinstance.py:1889} ERROR - Task failed with exception
Traceback (most recent call last):
  File "/home/james/airflowa/lib/python3.8/site-packages/airflow/operators/python.py", line 171, in execute
    return_value = self.execute_callable()
  File "/home/james/airflowa/lib/python3.8/site-packages/airflow/operators/python.py", line 189, in execute_callable
    return self.python_callable(*self.op_args, **self.op_kwargs)
  File "/home/james/airflow/dags/spotify_etl.py", line 49, in run_spotify_etl
    today = datetime.datetime.now()
AttributeError: type object 'datetime.datetime' has no attribute 'datetime'
[2022-06-08 12:21:48,613] {taskinstance.py:1395} INFO - Marking task as UP_FOR_RETRY. dag_id=spotify_dag, task_id=Whole_Spotify_ETL, execution_date=20220608T052100, start_date=20220608T092148, end_date=20220608T092148
[2022-06-08 12:21:48,626] {standard_task_runner.py:92} ERROR - Failed to execute job 349 for task Whole_Spotify_ETL (type object 'datetime.datetime' has no attribute 'datetime'; 104734)
[2022-06-08 12:21:48,648] {local_task_job.py:156} INFO - Task exited with return code 1
[2022-06-08 12:21:48,674] {local_task_job.py:273} INFO - 0 downstream tasks scheduled from follow-on schedule check
