[2022-06-08 12:56:26,654] {taskinstance.py:1159} INFO - Dependencies all met for <TaskInstance: spotify_dag.Whole_Spotify_ETL scheduled__2022-06-08T06:05:00+00:00 [queued]>
[2022-06-08 12:56:26,663] {taskinstance.py:1159} INFO - Dependencies all met for <TaskInstance: spotify_dag.Whole_Spotify_ETL scheduled__2022-06-08T06:05:00+00:00 [queued]>
[2022-06-08 12:56:26,663] {taskinstance.py:1356} INFO - 
--------------------------------------------------------------------------------
[2022-06-08 12:56:26,663] {taskinstance.py:1357} INFO - Starting attempt 2 of 2
[2022-06-08 12:56:26,663] {taskinstance.py:1358} INFO - 
--------------------------------------------------------------------------------
[2022-06-08 12:56:26,680] {taskinstance.py:1377} INFO - Executing <Task(PythonOperator): Whole_Spotify_ETL> on 2022-06-08 06:05:00+00:00
[2022-06-08 12:56:26,683] {standard_task_runner.py:52} INFO - Started process 123004 to run task
[2022-06-08 12:56:26,686] {standard_task_runner.py:79} INFO - Running: ['airflow', 'tasks', 'run', 'spotify_dag', 'Whole_Spotify_ETL', 'scheduled__2022-06-08T06:05:00+00:00', '--job-id', '467', '--raw', '--subdir', 'DAGS_FOLDER/spotify_dag.py', '--cfg-path', '/tmp/tmpg92f9k94', '--error-file', '/tmp/tmps9adugoc']
[2022-06-08 12:56:26,687] {standard_task_runner.py:80} INFO - Job 467: Subtask Whole_Spotify_ETL
[2022-06-08 12:56:26,730] {task_command.py:370} INFO - Running <TaskInstance: spotify_dag.Whole_Spotify_ETL scheduled__2022-06-08T06:05:00+00:00 [running]> on host kubernetes-worker
[2022-06-08 12:56:26,805] {taskinstance.py:1569} INFO - Exporting the following env vars:
AIRFLOW_CTX_DAG_EMAIL=wabuyajames@gmail.com
AIRFLOW_CTX_DAG_OWNER=airflow
AIRFLOW_CTX_DAG_ID=spotify_dag
AIRFLOW_CTX_TASK_ID=Whole_Spotify_ETL
AIRFLOW_CTX_EXECUTION_DATE=2022-06-08T06:05:00+00:00
AIRFLOW_CTX_TRY_NUMBER=2
AIRFLOW_CTX_DAG_RUN_ID=scheduled__2022-06-08T06:05:00+00:00
[2022-06-08 12:56:26,806] {taskinstance.py:1889} ERROR - Task failed with exception
Traceback (most recent call last):
  File "/home/james/airflowa/lib/python3.8/site-packages/airflow/operators/python.py", line 171, in execute
    return_value = self.execute_callable()
  File "/home/james/airflowa/lib/python3.8/site-packages/airflow/operators/python.py", line 189, in execute_callable
    return self.python_callable(*self.op_args, **self.op_kwargs)
  File "/home/james/airflow/dags/spotify_etl.py", line 49, in run_spotify_etl
    today = datetime.datetime.now()
AttributeError: type object 'datetime.datetime' has no attribute 'datetime'
[2022-06-08 12:56:26,809] {taskinstance.py:1395} INFO - Marking task as FAILED. dag_id=spotify_dag, task_id=Whole_Spotify_ETL, execution_date=20220608T060500, start_date=20220608T095626, end_date=20220608T095626
[2022-06-08 12:56:26,826] {logging_mixin.py:115} WARNING - /home/james/airflowa/lib/python3.8/site-packages/airflow/utils/email.py:119 PendingDeprecationWarning: Fetching SMTP credentials from configuration variables will be deprecated in a future release. Please set credentials using a connection instead.
[2022-06-08 12:56:26,826] {configuration.py:549} WARNING - section/key [smtp/smtp_user] not found in config
[2022-06-08 12:56:26,826] {email.py:228} INFO - Email alerting: attempt 1
[2022-06-08 12:56:26,830] {configuration.py:549} WARNING - section/key [smtp/smtp_user] not found in config
[2022-06-08 12:56:26,830] {email.py:228} INFO - Email alerting: attempt 1
[2022-06-08 12:56:26,830] {taskinstance.py:1944} ERROR - Failed to send email to: ['wabuyajames@gmail.com']
Traceback (most recent call last):
  File "/home/james/airflowa/lib/python3.8/site-packages/airflow/models/taskinstance.py", line 1451, in _run_raw_task
    self._execute_task_with_callbacks(context, test_mode)
  File "/home/james/airflowa/lib/python3.8/site-packages/airflow/models/taskinstance.py", line 1598, in _execute_task_with_callbacks
    result = self._execute_task(context, task_orig)
  File "/home/james/airflowa/lib/python3.8/site-packages/airflow/models/taskinstance.py", line 1659, in _execute_task
    result = execute_callable(context=context)
  File "/home/james/airflowa/lib/python3.8/site-packages/airflow/operators/python.py", line 171, in execute
    return_value = self.execute_callable()
  File "/home/james/airflowa/lib/python3.8/site-packages/airflow/operators/python.py", line 189, in execute_callable
    return self.python_callable(*self.op_args, **self.op_kwargs)
  File "/home/james/airflow/dags/spotify_etl.py", line 49, in run_spotify_etl
    today = datetime.datetime.now()
AttributeError: type object 'datetime.datetime' has no attribute 'datetime'

During handling of the above exception, another exception occurred:

Traceback (most recent call last):
  File "/home/james/airflowa/lib/python3.8/site-packages/airflow/models/taskinstance.py", line 2326, in email_alert
    send_email(task.email, subject, html_content)
  File "/home/james/airflowa/lib/python3.8/site-packages/airflow/utils/email.py", line 58, in send_email
    return backend(
  File "/home/james/airflowa/lib/python3.8/site-packages/airflow/utils/email.py", line 119, in send_email_smtp
    send_mime_email(e_from=mail_from, e_to=recipients, mime_msg=msg, conn_id=conn_id, dryrun=dryrun)
  File "/home/james/airflowa/lib/python3.8/site-packages/airflow/utils/email.py", line 230, in send_mime_email
    smtp_conn = _get_smtp_connection(smtp_host, smtp_port, smtp_timeout, smtp_ssl)
  File "/home/james/airflowa/lib/python3.8/site-packages/airflow/utils/email.py", line 264, in _get_smtp_connection
    else smtplib.SMTP(host=host, port=port, timeout=timeout)
  File "/usr/lib/python3.8/smtplib.py", line 255, in __init__
    (code, msg) = self.connect(host, port)
  File "/usr/lib/python3.8/smtplib.py", line 339, in connect
    self.sock = self._get_socket(host, port, self.timeout)
  File "/usr/lib/python3.8/smtplib.py", line 310, in _get_socket
    return socket.create_connection((host, port), timeout,
  File "/usr/lib/python3.8/socket.py", line 808, in create_connection
    raise err
  File "/usr/lib/python3.8/socket.py", line 796, in create_connection
    sock.connect(sa)
ConnectionRefusedError: [Errno 111] Connection refused

During handling of the above exception, another exception occurred:

Traceback (most recent call last):
  File "/home/james/airflowa/lib/python3.8/site-packages/airflow/models/taskinstance.py", line 1942, in handle_failure
    self.email_alert(error, task)
  File "/home/james/airflowa/lib/python3.8/site-packages/airflow/models/taskinstance.py", line 2328, in email_alert
    send_email(task.email, subject, html_content_err)
  File "/home/james/airflowa/lib/python3.8/site-packages/airflow/utils/email.py", line 58, in send_email
    return backend(
  File "/home/james/airflowa/lib/python3.8/site-packages/airflow/utils/email.py", line 119, in send_email_smtp
    send_mime_email(e_from=mail_from, e_to=recipients, mime_msg=msg, conn_id=conn_id, dryrun=dryrun)
  File "/home/james/airflowa/lib/python3.8/site-packages/airflow/utils/email.py", line 230, in send_mime_email
    smtp_conn = _get_smtp_connection(smtp_host, smtp_port, smtp_timeout, smtp_ssl)
  File "/home/james/airflowa/lib/python3.8/site-packages/airflow/utils/email.py", line 264, in _get_smtp_connection
    else smtplib.SMTP(host=host, port=port, timeout=timeout)
  File "/usr/lib/python3.8/smtplib.py", line 255, in __init__
    (code, msg) = self.connect(host, port)
  File "/usr/lib/python3.8/smtplib.py", line 339, in connect
    self.sock = self._get_socket(host, port, self.timeout)
  File "/usr/lib/python3.8/smtplib.py", line 310, in _get_socket
    return socket.create_connection((host, port), timeout,
  File "/usr/lib/python3.8/socket.py", line 808, in create_connection
    raise err
  File "/usr/lib/python3.8/socket.py", line 796, in create_connection
    sock.connect(sa)
ConnectionRefusedError: [Errno 111] Connection refused
[2022-06-08 12:56:26,840] {standard_task_runner.py:92} ERROR - Failed to execute job 467 for task Whole_Spotify_ETL (type object 'datetime.datetime' has no attribute 'datetime'; 123004)
[2022-06-08 12:56:26,858] {local_task_job.py:156} INFO - Task exited with return code 1
[2022-06-08 12:56:26,879] {local_task_job.py:273} INFO - 0 downstream tasks scheduled from follow-on schedule check
