[2022-06-08 12:52:44,754] {taskinstance.py:1159} INFO - Dependencies all met for <TaskInstance: spotify_dag.Whole_Spotify_ETL scheduled__2022-06-08T06:13:00+00:00 [queued]>
[2022-06-08 12:52:44,770] {taskinstance.py:1159} INFO - Dependencies all met for <TaskInstance: spotify_dag.Whole_Spotify_ETL scheduled__2022-06-08T06:13:00+00:00 [queued]>
[2022-06-08 12:52:44,771] {taskinstance.py:1356} INFO - 
--------------------------------------------------------------------------------
[2022-06-08 12:52:44,771] {taskinstance.py:1357} INFO - Starting attempt 1 of 2
[2022-06-08 12:52:44,771] {taskinstance.py:1358} INFO - 
--------------------------------------------------------------------------------
[2022-06-08 12:52:44,797] {taskinstance.py:1377} INFO - Executing <Task(PythonOperator): Whole_Spotify_ETL> on 2022-06-08 06:13:00+00:00
[2022-06-08 12:52:44,803] {standard_task_runner.py:52} INFO - Started process 121602 to run task
[2022-06-08 12:52:44,811] {standard_task_runner.py:79} INFO - Running: ['airflow', 'tasks', 'run', 'spotify_dag', 'Whole_Spotify_ETL', 'scheduled__2022-06-08T06:13:00+00:00', '--job-id', '454', '--raw', '--subdir', 'DAGS_FOLDER/spotify_dag.py', '--cfg-path', '/tmp/tmpkgr1k6z1', '--error-file', '/tmp/tmp7goofp3y']
[2022-06-08 12:52:44,812] {standard_task_runner.py:80} INFO - Job 454: Subtask Whole_Spotify_ETL
[2022-06-08 12:52:44,920] {task_command.py:370} INFO - Running <TaskInstance: spotify_dag.Whole_Spotify_ETL scheduled__2022-06-08T06:13:00+00:00 [running]> on host kubernetes-worker
[2022-06-08 12:52:45,049] {taskinstance.py:1569} INFO - Exporting the following env vars:
AIRFLOW_CTX_DAG_EMAIL=wabuyajames@gmail.com
AIRFLOW_CTX_DAG_OWNER=airflow
AIRFLOW_CTX_DAG_ID=spotify_dag
AIRFLOW_CTX_TASK_ID=Whole_Spotify_ETL
AIRFLOW_CTX_EXECUTION_DATE=2022-06-08T06:13:00+00:00
AIRFLOW_CTX_TRY_NUMBER=1
AIRFLOW_CTX_DAG_RUN_ID=scheduled__2022-06-08T06:13:00+00:00
[2022-06-08 12:52:45,051] {taskinstance.py:1889} ERROR - Task failed with exception
Traceback (most recent call last):
  File "/home/james/airflowa/lib/python3.8/site-packages/airflow/operators/python.py", line 171, in execute
    return_value = self.execute_callable()
  File "/home/james/airflowa/lib/python3.8/site-packages/airflow/operators/python.py", line 189, in execute_callable
    return self.python_callable(*self.op_args, **self.op_kwargs)
  File "/home/james/airflow/dags/spotify_etl.py", line 49, in run_spotify_etl
    today = datetime.datetime.now()
AttributeError: type object 'datetime.datetime' has no attribute 'datetime'
[2022-06-08 12:52:45,059] {taskinstance.py:1395} INFO - Marking task as UP_FOR_RETRY. dag_id=spotify_dag, task_id=Whole_Spotify_ETL, execution_date=20220608T061300, start_date=20220608T095244, end_date=20220608T095245
[2022-06-08 12:52:45,124] {standard_task_runner.py:92} ERROR - Failed to execute job 454 for task Whole_Spotify_ETL (type object 'datetime.datetime' has no attribute 'datetime'; 121602)
[2022-06-08 12:52:45,142] {local_task_job.py:156} INFO - Task exited with return code 1
[2022-06-08 12:52:45,198] {local_task_job.py:273} INFO - 0 downstream tasks scheduled from follow-on schedule check
